# Missing Exceptions Analysis
# This file tracks all exceptions used across the VerdoyLab API codebase

## EXCEPTIONS FOUND IN CODEBASE

### File: backend/app/exceptions.py (IMPLEMENTED)
- LMSException
- DatabaseConnectionException
- ConfigurationException
- CredentialsException
- TokenExpiredException
- InsufficientPermissionsException
- ResourceNotFoundException
- ValidationException
- ConflictException
- RateLimitException
- DatabaseException
- ExternalServiceException
- DeviceOfflineException
- CommandTimeoutException
- ServiceException
- NotFoundException
- UserAlreadyExistsException

### File: backend/app/database.py
- No custom exceptions found

### File: backend/app/config.py
- No custom exceptions found

### File: backend/app/dependencies.py
- CredentialsException (imported and used)
- TokenExpiredException (imported and used)
- HTTPException (from FastAPI, used directly)

### File: backend/app/__init__.py
- No custom exceptions found

### File: backend/app/schemas/__init__.py
- No custom exceptions found

### File: backend/app/schemas/base.py
- No custom exceptions found

### File: backend/app/schemas/user.py
- No custom exceptions found

### File: backend/app/schemas/device.py
- No custom exceptions found

### File: backend/app/schemas/reading.py
- No custom exceptions found

### File: backend/app/schemas/alert.py
- No custom exceptions found

### File: backend/app/schemas/billing.py
- No custom exceptions found

### File: backend/app/schemas/command.py
- No custom exceptions found

### File: backend/app/schemas/organization.py
- No custom exceptions found

### File: backend/app/models/__init__.py
- No custom exceptions found

### File: backend/app/models/base.py
- No custom exceptions found

### File: backend/app/models/user.py
- No custom exceptions found

### File: backend/app/models/device.py
- No custom exceptions found

### File: backend/app/models/reading.py
- No custom exceptions found

### File: backend/app/models/alert.py
- No custom exceptions found

### File: backend/app/models/billing.py
- No custom exceptions found

### File: backend/app/models/command.py
- No custom exceptions found

### File: backend/app/models/organization.py
- No custom exceptions found

### File: backend/app/models/entity.py
- No custom exceptions found

### File: backend/app/models/event.py
- No custom exceptions found

### File: backend/app/routers/__init__.py
- No custom exceptions found

### File: backend/app/routers/auth.py
- InactiveUserException (imported and used)

### File: backend/app/routers/devices.py
- DeviceNotFoundException (imported and used)
- AccessDeniedException (imported and used)
- DeviceAuthenticationException (imported and used)
- ValidationException (imported and used)

### File: backend/app/routers/readings.py
- DeviceNotFoundException (imported)

### File: backend/app/routers/commands.py
- DeviceNotFoundException (imported and used)

### File: backend/app/routers/alerts.py
- No custom exceptions found

### File: backend/app/routers/analytics.py
- No custom exceptions found

### File: backend/app/routers/billing.py
- No custom exceptions found

### File: backend/app/routers/organizations.py
- No custom exceptions found

### File: backend/app/routers/admin.py
- No custom exceptions found

### File: backend/app/routers/system.py
- No custom exceptions found

### File: backend/app/routers/health.py
- No custom exceptions found

### File: backend/app/services/__init__.py
- No custom exceptions found

### File: backend/app/services/base.py
- ServiceException (imported and used)
- ValidationException (imported and used)
- DatabaseException (imported and used)
- NotFoundException (imported and used)

### File: backend/app/services/auth_service.py
- ServiceException (imported and used)
- ValidationException (imported and used)
- UserAlreadyExistsException (imported and used)
- AuthenticationException (imported and used)
- InactiveUserException (imported and used)

### File: backend/app/services/device_service.py
- ServiceException (imported and used)
- ValidationException (imported and used)
- DeviceAlreadyExistsException (imported and used)
- DeviceNotFoundException (imported and used)
- DeviceOfflineException (imported)

### File: backend/app/services/reading_service.py
- ServiceException (imported and used)
- ValidationException (imported and used)
- DeviceNotFoundException (imported and used)
- DataProcessingException (imported)

### File: backend/app/services/command_service.py
- No custom exceptions found

### File: backend/app/services/alert_service.py
- No custom exceptions found

### File: backend/app/services/analytics_service.py
- No custom exceptions found

### File: backend/app/services/billing_service.py
- No custom exceptions found

### File: backend/app/services/organization_service.py
- ServiceException (imported and used)
- ValidationException (imported and used)
- OrganizationAlreadyExistsException (imported and used)
- OrganizationNotFoundException (imported)
- UserNotFoundException (imported and used)

### File: backend/app/services/cache_service.py
- No custom exceptions found

### File: backend/app/services/notification_service.py
- No custom exceptions found

### File: backend/app/services/background_service.py
- No custom exceptions found

### File: backend/app/services/websocket_service.py
- No custom exceptions found

### File: backend/app/utils/__init__.py
- No custom exceptions found

### File: backend/app/utils/helpers.py
- No custom exceptions found

### File: backend/app/utils/validators.py
- No custom exceptions found

### File: backend/app/utils/exporters.py
- No custom exceptions found

### File: backend/app/middleware/__init__.py
- No custom exceptions found

### File: backend/app/middleware/cors.py
- No custom exceptions found

### File: backend/app/middleware/logging.py
- No custom exceptions found

### File: backend/app/middleware/websocket.py
- No custom exceptions found

### File: backend/tests/__init__.py
- No custom exceptions found

### File: backend/tests/conftest.py
- FileNotFoundError (built-in Python exception)

### File: backend/tests/test_api/__init__.py
- No custom exceptions found

### File: backend/tests/test_api/test_auth.py
- No custom exceptions found

### File: backend/tests/test_api/test_devices.py
- No custom exceptions found

### File: backend/tests/test_core/__init__.py
- No custom exceptions found

### File: backend/tests/test_core/test_auth_service.py
- UserAlreadyExistsException (imported and used in tests)
- ValidationException (imported and used in tests)
- AuthenticationException (imported and used in tests)

### File: backend/tests/test_core/test_device_service.py
- DeviceAlreadyExistsException (imported and used in tests)
- ValidationException (imported and used in tests)
- DeviceNotFoundException (imported and used in tests)

### File: backend/tests/test_core/test_reading_service.py
- ValidationException (imported and used in tests)
- ReadingNotFoundException (imported and used in tests)

## MISSING EXCEPTIONS (NOT IMPLEMENTED IN exceptions.py)

### ðŸ”´ CRITICAL MISSING EXCEPTIONS

1. **AuthenticationException**
   - Used in: auth_service.py, test_auth_service.py
   - Purpose: Authentication failures (invalid credentials)
   - Status: MISSING - Not defined in exceptions.py

2. **InactiveUserException**
   - Used in: auth_service.py, routers/auth.py, test_auth_service.py
   - Purpose: User account is deactivated
   - Status: MISSING - Not defined in exceptions.py

3. **UserNotFoundException**
   - Used in: organization_service.py
   - Purpose: User not found in database
   - Status: MISSING - Not defined in exceptions.py

4. **DeviceNotFoundException**
   - Used in: device_service.py, reading_service.py, routers/devices.py, routers/readings.py, routers/commands.py, test_device_service.py
   - Purpose: Device not found in database
   - Status: MISSING - Not defined in exceptions.py

5. **DeviceAlreadyExistsException**
   - Used in: device_service.py, test_device_service.py
   - Purpose: Device with same serial number already exists
   - Status: MISSING - Not defined in exceptions.py

6. **DeviceAuthenticationException**
   - Used in: routers/devices.py
   - Purpose: Device authentication failures (ID mismatch)
   - Status: MISSING - Not defined in exceptions.py

7. **OrganizationAlreadyExistsException**
   - Used in: organization_service.py
   - Purpose: Organization with same name already exists
   - Status: MISSING - Not defined in exceptions.py

8. **OrganizationNotFoundException**
   - Used in: organization_service.py (imported but not used)
   - Purpose: Organization not found in database
   - Status: MISSING - Not defined in exceptions.py

9. **ReadingNotFoundException**
   - Used in: test_reading_service.py
   - Purpose: Reading not found in database
   - Status: MISSING - Not defined in exceptions.py

10. **DataProcessingException**
    - Used in: reading_service.py (imported but not used)
    - Purpose: Data processing failures
    - Status: MISSING - Not defined in exceptions.py

11. **AccessDeniedException**
    - Used in: routers/devices.py
    - Purpose: Access denied to resource
    - Status: MISSING - Not defined in exceptions.py

### ðŸŸ¡ POTENTIALLY MISSING EXCEPTIONS

1. **DeviceOfflineException**
   - Used in: device_service.py (imported but not used)
   - Purpose: Device is offline when operation requires online status
   - Status: IMPLEMENTED - Already defined in exceptions.py

## SUMMARY

**Total Missing Exceptions: 11**

The codebase has 11 critical exceptions that are being used throughout the application but are not defined in the exceptions.py file. These missing exceptions are causing import errors and runtime failures in the application.

**Priority for Implementation:**
1. **HIGH**: AuthenticationException, InactiveUserException, UserNotFoundException, DeviceNotFoundException, DeviceAlreadyExistsException
2. **MEDIUM**: DeviceAuthenticationException, OrganizationAlreadyExistsException, OrganizationNotFoundException, ReadingNotFoundException
3. **LOW**: DataProcessingException, AccessDeniedException

All missing exceptions should be implemented in exceptions.py to ensure the application functions correctly. 